#
# <meta:header>
#   <meta:licence>
#     Copyright (c) 2014, ROE (http://www.roe.ac.uk/)
#
#     This information is free software: you can redistribute it and/or modify
#     it under the terms of the GNU General Public License as published by
#     the Free Software Foundation, either version 3 of the License, or
#     (at your option) any later version.
#
#     This information is distributed in the hope that it will be useful,
#     but WITHOUT ANY WARRANTY; without even the implied warranty of
#     MERCHANTABILITY or FITNESS FOR A PARTICULAR PURPOSE.  See the
#     GNU General Public License for more details.
#  
#     You should have received a copy of the GNU General Public License
#     along with this program.  If not, see <http://www.gnu.org/licenses/>.
#   </meta:licence>
# </meta:header>
#
#

[Stevedore@Siamond ~]$ docker exec -it stevedore_firethorn-py_run_2 bash

[root@firethorn-py firethorn-py]# python3
Python 3.6.5 (default, Mar 29 2018, 18:20:46) 
[GCC 8.0.1 20180317 (Red Hat 8.0.1-0.19)] on linux
Type "help", "copyright", "credits" or "license" for more information.


>> import firethorn
>> import firethorn_utils.configurator as configur
>> ft = firethorn.Firethorn(endpoint="http://tap.roe.ac.uk/firethorn")
>> ft.login(firethorn.config.adminuser, firethorn.config.adminpass, firethorn.config.admingroup)
>> configurator =  configur.Configurator(ft)
>> configurator.load_resources("https://raw.githubusercontent.com/stvoutsin/firethorn.py/master/firethorn/data/osa-tap.json")

Importing JDBC Schema: ATLASDR1
Importing JDBC Schema: ATLASDR2
Importing JDBC Schema: ATLASDR3
Importing JDBC Schema: 2MASS
ERROR:root:HTTP Error 404: 
Traceback (most recent call last):
  File "/usr/local/lib/python3.5/dist-packages/firethorn/models/base/base_object.py", line 91, in get_json
    with urllib.request.urlopen( req, data) as response:
  File "/usr/lib/python3.5/urllib/request.py", line 163, in urlopen
    return opener.open(url, data, timeout)
  File "/usr/lib/python3.5/urllib/request.py", line 472, in open
    response = meth(req, response)
  File "/usr/lib/python3.5/urllib/request.py", line 582, in http_response
    'http', request, response, code, msg, hdrs)
  File "/usr/lib/python3.5/urllib/request.py", line 510, in error
    return self._call_chain(*args)
  File "/usr/lib/python3.5/urllib/request.py", line 444, in _call_chain
    result = func(*args)
  File "/usr/lib/python3.5/urllib/request.py", line 590, in http_error_default
    raise HTTPError(req.full_url, code, msg, hdrs, fp)
urllib.error.HTTPError: HTTP Error 404: 
ERROR:root:Expecting value: line 1 column 1 (char 0)
Traceback (most recent call last):
  File "/usr/local/lib/python3.5/dist-packages/firethorn/models/adql/adql_resource.py", line 112, in import_jdbc_schema
    response_json_list = json.loads(response.text)
  File "/usr/lib/python3.5/json/__init__.py", line 319, in loads
    return _default_decoder.decode(s)
  File "/usr/lib/python3.5/json/decoder.py", line 339, in decode
    obj, end = self.raw_decode(s, idx=_w(s, 0).end())
  File "/usr/lib/python3.5/json/decoder.py", line 357, in raw_decode
    raise JSONDecodeError("Expecting value", s, err.value) from None
json.decoder.JSONDecodeError: Expecting value: line 1 column 1 (char 0)
Importing JDBC Schema: 2XMM
ERROR:root:HTTP Error 404: 
Traceback (most recent call last):
  File "/usr/local/lib/python3.5/dist-packages/firethorn/models/base/base_object.py", line 91, in get_json
    with urllib.request.urlopen( req, data) as response:
  File "/usr/lib/python3.5/urllib/request.py", line 163, in urlopen
    return opener.open(url, data, timeout)
  File "/usr/lib/python3.5/urllib/request.py", line 472, in open
    response = meth(req, response)
  File "/usr/lib/python3.5/urllib/request.py", line 582, in http_response
    'http', request, response, code, msg, hdrs)
  File "/usr/lib/python3.5/urllib/request.py", line 510, in error
    return self._call_chain(*args)
  File "/usr/lib/python3.5/urllib/request.py", line 444, in _call_chain
    result = func(*args)
  File "/usr/lib/python3.5/urllib/request.py", line 590, in http_error_default
    raise HTTPError(req.full_url, code, msg, hdrs, fp)
urllib.error.HTTPError: HTTP Error 404: 
ERROR:root:Expecting value: line 1 column 1 (char 0)
Traceback (most recent call last):
  File "/usr/local/lib/python3.5/dist-packages/firethorn/models/adql/adql_resource.py", line 112, in import_jdbc_schema
    response_json_list = json.loads(response.text)
  File "/usr/lib/python3.5/json/__init__.py", line 319, in loads
    return _default_decoder.decode(s)
  File "/usr/lib/python3.5/json/decoder.py", line 339, in decode
    obj, end = self.raw_decode(s, idx=_w(s, 0).end())
  File "/usr/lib/python3.5/json/decoder.py", line 357, in raw_decode
    raise JSONDecodeError("Expecting value", s, err.value) from None
json.decoder.JSONDecodeError: Expecting value: line 1 column 1 (char 0)
Importing JDBC Schema: WISE
ERROR:root:HTTP Error 404: 
Traceback (most recent call last):
  File "/usr/local/lib/python3.5/dist-packages/firethorn/models/base/base_object.py", line 91, in get_json
    with urllib.request.urlopen( req, data) as response:
  File "/usr/lib/python3.5/urllib/request.py", line 163, in urlopen
    return opener.open(url, data, timeout)
  File "/usr/lib/python3.5/urllib/request.py", line 472, in open
    response = meth(req, response)
  File "/usr/lib/python3.5/urllib/request.py", line 582, in http_response
    'http', request, response, code, msg, hdrs)
  File "/usr/lib/python3.5/urllib/request.py", line 510, in error
    return self._call_chain(*args)
  File "/usr/lib/python3.5/urllib/request.py", line 444, in _call_chain
    result = func(*args)
  File "/usr/lib/python3.5/urllib/request.py", line 590, in http_error_default
    raise HTTPError(req.full_url, code, msg, hdrs, fp)
urllib.error.HTTPError: HTTP Error 404: 
ERROR:root:Expecting value: line 1 column 1 (char 0)
Traceback (most recent call last):
  File "/usr/local/lib/python3.5/dist-packages/firethorn/models/adql/adql_resource.py", line 112, in import_jdbc_schema
    response_json_list = json.loads(response.text)
  File "/usr/lib/python3.5/json/__init__.py", line 319, in loads
    return _default_decoder.decode(s)
  File "/usr/lib/python3.5/json/decoder.py", line 339, in decode
    obj, end = self.raw_decode(s, idx=_w(s, 0).end())
  File "/usr/lib/python3.5/json/decoder.py", line 357, in raw_decode
    raise JSONDecodeError("Expecting value", s, err.value) from None
json.decoder.JSONDecodeError: Expecting value: line 1 column 1 (char 0)
Importing JDBC Schema: VIKINGDR3
Importing JDBC Schema: VHSDR1
Importing JDBC Schema: MGC
ERROR:root:HTTP Error 404: 
Traceback (most recent call last):
  File "/usr/local/lib/python3.5/dist-packages/firethorn/models/base/base_object.py", line 91, in get_json
    with urllib.request.urlopen( req, data) as response:
  File "/usr/lib/python3.5/urllib/request.py", line 163, in urlopen
    return opener.open(url, data, timeout)
  File "/usr/lib/python3.5/urllib/request.py", line 472, in open
    response = meth(req, response)
  File "/usr/lib/python3.5/urllib/request.py", line 582, in http_response
    'http', request, response, code, msg, hdrs)
  File "/usr/lib/python3.5/urllib/request.py", line 510, in error
    return self._call_chain(*args)
  File "/usr/lib/python3.5/urllib/request.py", line 444, in _call_chain
    result = func(*args)
  File "/usr/lib/python3.5/urllib/request.py", line 590, in http_error_default
    raise HTTPError(req.full_url, code, msg, hdrs, fp)
urllib.error.HTTPError: HTTP Error 404: 
ERROR:root:Expecting value: line 1 column 1 (char 0)
Traceback (most recent call last):
  File "/usr/local/lib/python3.5/dist-packages/firethorn/models/adql/adql_resource.py", line 112, in import_jdbc_schema
    response_json_list = json.loads(response.text)
  File "/usr/lib/python3.5/json/__init__.py", line 319, in loads
    return _default_decoder.decode(s)
  File "/usr/lib/python3.5/json/decoder.py", line 339, in decode
    obj, end = self.raw_decode(s, idx=_w(s, 0).end())
  File "/usr/lib/python3.5/json/decoder.py", line 357, in raw_decode
    raise JSONDecodeError("Expecting value", s, err.value) from None
json.decoder.JSONDecodeError: Expecting value: line 1 column 1 (char 0)
Importing JDBC Schema: GLIMPSE
ERROR:root:HTTP Error 404: 
Traceback (most recent call last):
  File "/usr/local/lib/python3.5/dist-packages/firethorn/models/base/base_object.py", line 91, in get_json
    with urllib.request.urlopen( req, data) as response:
  File "/usr/lib/python3.5/urllib/request.py", line 163, in urlopen
    return opener.open(url, data, timeout)
  File "/usr/lib/python3.5/urllib/request.py", line 472, in open
    response = meth(req, response)
  File "/usr/lib/python3.5/urllib/request.py", line 582, in http_response
    'http', request, response, code, msg, hdrs)
  File "/usr/lib/python3.5/urllib/request.py", line 510, in error
    return self._call_chain(*args)
  File "/usr/lib/python3.5/urllib/request.py", line 444, in _call_chain
    result = func(*args)
  File "/usr/lib/python3.5/urllib/request.py", line 590, in http_error_default
    raise HTTPError(req.full_url, code, msg, hdrs, fp)
urllib.error.HTTPError: HTTP Error 404: 
ERROR:root:Expecting value: line 1 column 1 (char 0)
Traceback (most recent call last):
  File "/usr/local/lib/python3.5/dist-packages/firethorn/models/adql/adql_resource.py", line 112, in import_jdbc_schema
    response_json_list = json.loads(response.text)
  File "/usr/lib/python3.5/json/__init__.py", line 319, in loads
    return _default_decoder.decode(s)
  File "/usr/lib/python3.5/json/decoder.py", line 339, in decode
    obj, end = self.raw_decode(s, idx=_w(s, 0).end())
  File "/usr/lib/python3.5/json/decoder.py", line 357, in raw_decode
    raise JSONDecodeError("Expecting value", s, err.value) from None
json.decoder.JSONDecodeError: Expecting value: line 1 column 1 (char 0)
Importing JDBC Schema: FIRST
ERROR:root:HTTP Error 404: 
Traceback (most recent call last):
  File "/usr/local/lib/python3.5/dist-packages/firethorn/models/base/base_object.py", line 91, in get_json
    with urllib.request.urlopen( req, data) as response:
  File "/usr/lib/python3.5/urllib/request.py", line 163, in urlopen
    return opener.open(url, data, timeout)
  File "/usr/lib/python3.5/urllib/request.py", line 472, in open
    response = meth(req, response)
  File "/usr/lib/python3.5/urllib/request.py", line 582, in http_response
    'http', request, response, code, msg, hdrs)
  File "/usr/lib/python3.5/urllib/request.py", line 510, in error
    return self._call_chain(*args)
  File "/usr/lib/python3.5/urllib/request.py", line 444, in _call_chain
    result = func(*args)
  File "/usr/lib/python3.5/urllib/request.py", line 590, in http_error_default
    raise HTTPError(req.full_url, code, msg, hdrs, fp)
urllib.error.HTTPError: HTTP Error 404: 
ERROR:root:Expecting value: line 1 column 1 (char 0)
Traceback (most recent call last):
  File "/usr/local/lib/python3.5/dist-packages/firethorn/models/adql/adql_resource.py", line 112, in import_jdbc_schema
    response_json_list = json.loads(response.text)
  File "/usr/lib/python3.5/json/__init__.py", line 319, in loads
    return _default_decoder.decode(s)
  File "/usr/lib/python3.5/json/decoder.py", line 339, in decode
    obj, end = self.raw_decode(s, idx=_w(s, 0).end())
  File "/usr/lib/python3.5/json/decoder.py", line 357, in raw_decode
    raise JSONDecodeError("Expecting value", s, err.value) from None
json.decoder.JSONDecodeError: Expecting value: line 1 column 1 (char 0)
Importing JDBC Schema: DENIS
ERROR:root:HTTP Error 404: 
Traceback (most recent call last):
  File "/usr/local/lib/python3.5/dist-packages/firethorn/models/base/base_object.py", line 91, in get_json
    with urllib.request.urlopen( req, data) as response:
  File "/usr/lib/python3.5/urllib/request.py", line 163, in urlopen
    return opener.open(url, data, timeout)
  File "/usr/lib/python3.5/urllib/request.py", line 472, in open
    response = meth(req, response)
  File "/usr/lib/python3.5/urllib/request.py", line 582, in http_response
    'http', request, response, code, msg, hdrs)
  File "/usr/lib/python3.5/urllib/request.py", line 510, in error
    return self._call_chain(*args)
  File "/usr/lib/python3.5/urllib/request.py", line 444, in _call_chain
    result = func(*args)
  File "/usr/lib/python3.5/urllib/request.py", line 590, in http_error_default
    raise HTTPError(req.full_url, code, msg, hdrs, fp)
urllib.error.HTTPError: HTTP Error 404: 
ERROR:root:Expecting value: line 1 column 1 (char 0)
Traceback (most recent call last):
  File "/usr/local/lib/python3.5/dist-packages/firethorn/models/adql/adql_resource.py", line 112, in import_jdbc_schema
    response_json_list = json.loads(response.text)
  File "/usr/lib/python3.5/json/__init__.py", line 319, in loads
    return _default_decoder.decode(s)
  File "/usr/lib/python3.5/json/decoder.py", line 339, in decode
    obj, end = self.raw_decode(s, idx=_w(s, 0).end())
  File "/usr/lib/python3.5/json/decoder.py", line 357, in raw_decode
    raise JSONDecodeError("Expecting value", s, err.value) from None
json.decoder.JSONDecodeError: Expecting value: line 1 column 1 (char 0)
TAP Service available at: http://tap.roe.ac.uk/firethorn/tap/21803708/


New ADQL TAP Service: http://tap.roe.ac.uk/firethorn/tap/21803708/

