#
# <meta:header>
#   <meta:licence>
#     Copyright (c) 2018, ROE (http://www.roe.ac.uk/)
#
#     This information is free software: you can redistribute it and/or modify
#     it under the terms of the GNU General Public License as published by
#     the Free Software Foundation, either version 3 of the License, or
#     (at your option) any later version.
#
#     This information is distributed in the hope that it will be useful,
#     but WITHOUT ANY WARRANTY; without even the implied warranty of
#     MERCHANTABILITY or FITNESS FOR A PARTICULAR PURPOSE.  See the
#     GNU General Public License for more details.
#
#     You should have received a copy of the GNU General Public License
#     along with this program.  If not, see <http://www.gnu.org/licenses/>.
#   </meta:licence>
# </meta:header>
#
#

    #
    # Lots of 404 errors loading JDBC Schema.
    # Very little information in the firethorn logs.
    # Need to check what these mean.
    #


    >>> # -----------------------------------------------------
    ... # Run our Python installer.
    ... #[python]
    ...

    ...
    ...
    ...

    >>> #
    ... # Load the OSA configutarion.
    ... configurator.load_resources(
    ...     "https://raw.githubusercontent.com/wfau/metadata/master/firethorn/config/osa-tap.json"
    ...     )
    Importing JDBC Schema: ATLASDR1
    Importing JDBC Schema: ATLASDR2
    Importing JDBC Schema: ATLASDR3
    Importing JDBC Schema: 2MASS
    ERROR:root:HTTP Error 404:
    Traceback (most recent call last):
      File "/usr/local/lib/python3.5/dist-packages/firethorn/models/base/base_object.py", line 90, in get_json
        with urllib.request.urlopen( req, data) as response:
      File "/usr/lib/python3.5/urllib/request.py", line 163, in urlopen
        return opener.open(url, data, timeout)
      File "/usr/lib/python3.5/urllib/request.py", line 472, in open
        response = meth(req, response)
      File "/usr/lib/python3.5/urllib/request.py", line 582, in http_response
        'http', request, response, code, msg, hdrs)
      File "/usr/lib/python3.5/urllib/request.py", line 510, in error
        return self._call_chain(*args)
      File "/usr/lib/python3.5/urllib/request.py", line 444, in _call_chain
        result = func(*args)
      File "/usr/lib/python3.5/urllib/request.py", line 590, in http_error_default
        raise HTTPError(req.full_url, code, msg, hdrs, fp)
    urllib.error.HTTPError: HTTP Error 404:
    ERROR:root:Expecting value: line 1 column 1 (char 0)
    Traceback (most recent call last):
      File "/usr/local/lib/python3.5/dist-packages/firethorn/models/adql/adql_resource.py", line 112, in import_jdbc_schema
        response_json_list = json.loads(response.text)
      File "/usr/lib/python3.5/json/__init__.py", line 319, in loads
        return _default_decoder.decode(s)
      File "/usr/lib/python3.5/json/decoder.py", line 339, in decode
        obj, end = self.raw_decode(s, idx=_w(s, 0).end())
      File "/usr/lib/python3.5/json/decoder.py", line 357, in raw_decode
        raise JSONDecodeError("Expecting value", s, err.value) from None
    json.decoder.JSONDecodeError: Expecting value: line 1 column 1 (char 0)
    Importing JDBC Schema: 2XMM
    ERROR:root:HTTP Error 404:
    Traceback (most recent call last):
      File "/usr/local/lib/python3.5/dist-packages/firethorn/models/base/base_object.py", line 90, in get_json
        with urllib.request.urlopen( req, data) as response:
      File "/usr/lib/python3.5/urllib/request.py", line 163, in urlopen
        return opener.open(url, data, timeout)
      File "/usr/lib/python3.5/urllib/request.py", line 472, in open
        response = meth(req, response)
      File "/usr/lib/python3.5/urllib/request.py", line 582, in http_response
        'http', request, response, code, msg, hdrs)
      File "/usr/lib/python3.5/urllib/request.py", line 510, in error
        return self._call_chain(*args)
      File "/usr/lib/python3.5/urllib/request.py", line 444, in _call_chain
        result = func(*args)
      File "/usr/lib/python3.5/urllib/request.py", line 590, in http_error_default
        raise HTTPError(req.full_url, code, msg, hdrs, fp)
    urllib.error.HTTPError: HTTP Error 404:
    ERROR:root:Expecting value: line 1 column 1 (char 0)
    Traceback (most recent call last):
      File "/usr/local/lib/python3.5/dist-packages/firethorn/models/adql/adql_resource.py", line 112, in import_jdbc_schema
        response_json_list = json.loads(response.text)
      File "/usr/lib/python3.5/json/__init__.py", line 319, in loads
        return _default_decoder.decode(s)
      File "/usr/lib/python3.5/json/decoder.py", line 339, in decode
        obj, end = self.raw_decode(s, idx=_w(s, 0).end())
      File "/usr/lib/python3.5/json/decoder.py", line 357, in raw_decode
        raise JSONDecodeError("Expecting value", s, err.value) from None
    json.decoder.JSONDecodeError: Expecting value: line 1 column 1 (char 0)
    Importing JDBC Schema: WISE
    ERROR:root:HTTP Error 404:
    Traceback (most recent call last):
      File "/usr/local/lib/python3.5/dist-packages/firethorn/models/base/base_object.py", line 90, in get_json
        with urllib.request.urlopen( req, data) as response:
      File "/usr/lib/python3.5/urllib/request.py", line 163, in urlopen
        return opener.open(url, data, timeout)
      File "/usr/lib/python3.5/urllib/request.py", line 472, in open
        response = meth(req, response)
      File "/usr/lib/python3.5/urllib/request.py", line 582, in http_response
        'http', request, response, code, msg, hdrs)
      File "/usr/lib/python3.5/urllib/request.py", line 510, in error
        return self._call_chain(*args)
      File "/usr/lib/python3.5/urllib/request.py", line 444, in _call_chain
        result = func(*args)
      File "/usr/lib/python3.5/urllib/request.py", line 590, in http_error_default
        raise HTTPError(req.full_url, code, msg, hdrs, fp)
    urllib.error.HTTPError: HTTP Error 404:
    ERROR:root:Expecting value: line 1 column 1 (char 0)
    Traceback (most recent call last):
      File "/usr/local/lib/python3.5/dist-packages/firethorn/models/adql/adql_resource.py", line 112, in import_jdbc_schema
        response_json_list = json.loads(response.text)
      File "/usr/lib/python3.5/json/__init__.py", line 319, in loads
        return _default_decoder.decode(s)
      File "/usr/lib/python3.5/json/decoder.py", line 339, in decode
        obj, end = self.raw_decode(s, idx=_w(s, 0).end())
      File "/usr/lib/python3.5/json/decoder.py", line 357, in raw_decode
        raise JSONDecodeError("Expecting value", s, err.value) from None
    json.decoder.JSONDecodeError: Expecting value: line 1 column 1 (char 0)
    Importing JDBC Schema: VIKINGDR3
    Importing JDBC Schema: VHSDR1
    Importing JDBC Schema: MGC
    ERROR:root:HTTP Error 404:
    Traceback (most recent call last):
      File "/usr/local/lib/python3.5/dist-packages/firethorn/models/base/base_object.py", line 90, in get_json
        with urllib.request.urlopen( req, data) as response:
      File "/usr/lib/python3.5/urllib/request.py", line 163, in urlopen
        return opener.open(url, data, timeout)
      File "/usr/lib/python3.5/urllib/request.py", line 472, in open
        response = meth(req, response)
      File "/usr/lib/python3.5/urllib/request.py", line 582, in http_response
        'http', request, response, code, msg, hdrs)
      File "/usr/lib/python3.5/urllib/request.py", line 510, in error
        return self._call_chain(*args)
      File "/usr/lib/python3.5/urllib/request.py", line 444, in _call_chain
        result = func(*args)
      File "/usr/lib/python3.5/urllib/request.py", line 590, in http_error_default
        raise HTTPError(req.full_url, code, msg, hdrs, fp)
    urllib.error.HTTPError: HTTP Error 404:
    ERROR:root:Expecting value: line 1 column 1 (char 0)
    Traceback (most recent call last):
      File "/usr/local/lib/python3.5/dist-packages/firethorn/models/adql/adql_resource.py", line 112, in import_jdbc_schema
        response_json_list = json.loads(response.text)
      File "/usr/lib/python3.5/json/__init__.py", line 319, in loads
        return _default_decoder.decode(s)
      File "/usr/lib/python3.5/json/decoder.py", line 339, in decode
        obj, end = self.raw_decode(s, idx=_w(s, 0).end())
      File "/usr/lib/python3.5/json/decoder.py", line 357, in raw_decode
        raise JSONDecodeError("Expecting value", s, err.value) from None
    json.decoder.JSONDecodeError: Expecting value: line 1 column 1 (char 0)
    Importing JDBC Schema: GLIMPSE
    ERROR:root:HTTP Error 404:
    Traceback (most recent call last):
      File "/usr/local/lib/python3.5/dist-packages/firethorn/models/base/base_object.py", line 90, in get_json
        with urllib.request.urlopen( req, data) as response:
      File "/usr/lib/python3.5/urllib/request.py", line 163, in urlopen
        return opener.open(url, data, timeout)
      File "/usr/lib/python3.5/urllib/request.py", line 472, in open
        response = meth(req, response)
      File "/usr/lib/python3.5/urllib/request.py", line 582, in http_response
        'http', request, response, code, msg, hdrs)
      File "/usr/lib/python3.5/urllib/request.py", line 510, in error
        return self._call_chain(*args)
      File "/usr/lib/python3.5/urllib/request.py", line 444, in _call_chain
        result = func(*args)
      File "/usr/lib/python3.5/urllib/request.py", line 590, in http_error_default
        raise HTTPError(req.full_url, code, msg, hdrs, fp)
    urllib.error.HTTPError: HTTP Error 404:
    ERROR:root:Expecting value: line 1 column 1 (char 0)
    Traceback (most recent call last):
      File "/usr/local/lib/python3.5/dist-packages/firethorn/models/adql/adql_resource.py", line 112, in import_jdbc_schema
        response_json_list = json.loads(response.text)
      File "/usr/lib/python3.5/json/__init__.py", line 319, in loads
        return _default_decoder.decode(s)
      File "/usr/lib/python3.5/json/decoder.py", line 339, in decode
        obj, end = self.raw_decode(s, idx=_w(s, 0).end())
      File "/usr/lib/python3.5/json/decoder.py", line 357, in raw_decode
        raise JSONDecodeError("Expecting value", s, err.value) from None
    json.decoder.JSONDecodeError: Expecting value: line 1 column 1 (char 0)
    Importing JDBC Schema: FIRST
    ERROR:root:HTTP Error 404:
    Traceback (most recent call last):
      File "/usr/local/lib/python3.5/dist-packages/firethorn/models/base/base_object.py", line 90, in get_json
        with urllib.request.urlopen( req, data) as response:
      File "/usr/lib/python3.5/urllib/request.py", line 163, in urlopen
        return opener.open(url, data, timeout)
      File "/usr/lib/python3.5/urllib/request.py", line 472, in open
        response = meth(req, response)
      File "/usr/lib/python3.5/urllib/request.py", line 582, in http_response
        'http', request, response, code, msg, hdrs)
      File "/usr/lib/python3.5/urllib/request.py", line 510, in error
        return self._call_chain(*args)
      File "/usr/lib/python3.5/urllib/request.py", line 444, in _call_chain
        result = func(*args)
      File "/usr/lib/python3.5/urllib/request.py", line 590, in http_error_default
        raise HTTPError(req.full_url, code, msg, hdrs, fp)
    urllib.error.HTTPError: HTTP Error 404:
    ERROR:root:Expecting value: line 1 column 1 (char 0)
    Traceback (most recent call last):
      File "/usr/local/lib/python3.5/dist-packages/firethorn/models/adql/adql_resource.py", line 112, in import_jdbc_schema
        response_json_list = json.loads(response.text)
      File "/usr/lib/python3.5/json/__init__.py", line 319, in loads
        return _default_decoder.decode(s)
      File "/usr/lib/python3.5/json/decoder.py", line 339, in decode
        obj, end = self.raw_decode(s, idx=_w(s, 0).end())
      File "/usr/lib/python3.5/json/decoder.py", line 357, in raw_decode
        raise JSONDecodeError("Expecting value", s, err.value) from None
    json.decoder.JSONDecodeError: Expecting value: line 1 column 1 (char 0)
    Importing JDBC Schema: DENIS
    ERROR:root:HTTP Error 404:
    Traceback (most recent call last):
      File "/usr/local/lib/python3.5/dist-packages/firethorn/models/base/base_object.py", line 90, in get_json
        with urllib.request.urlopen( req, data) as response:
      File "/usr/lib/python3.5/urllib/request.py", line 163, in urlopen
        return opener.open(url, data, timeout)
      File "/usr/lib/python3.5/urllib/request.py", line 472, in open
        response = meth(req, response)
      File "/usr/lib/python3.5/urllib/request.py", line 582, in http_response
        'http', request, response, code, msg, hdrs)
      File "/usr/lib/python3.5/urllib/request.py", line 510, in error
        return self._call_chain(*args)
      File "/usr/lib/python3.5/urllib/request.py", line 444, in _call_chain
        result = func(*args)
      File "/usr/lib/python3.5/urllib/request.py", line 590, in http_error_default
        raise HTTPError(req.full_url, code, msg, hdrs, fp)
    urllib.error.HTTPError: HTTP Error 404:
    ERROR:root:Expecting value: line 1 column 1 (char 0)
    Traceback (most recent call last):
      File "/usr/local/lib/python3.5/dist-packages/firethorn/models/adql/adql_resource.py", line 112, in import_jdbc_schema
        response_json_list = json.loads(response.text)
      File "/usr/lib/python3.5/json/__init__.py", line 319, in loads
        return _default_decoder.decode(s)
      File "/usr/lib/python3.5/json/decoder.py", line 339, in decode
        obj, end = self.raw_decode(s, idx=_w(s, 0).end())
      File "/usr/lib/python3.5/json/decoder.py", line 357, in raw_decode
        raise JSONDecodeError("Expecting value", s, err.value) from None
    json.decoder.JSONDecodeError: Expecting value: line 1 column 1 (char 0)
    Importing JDBC Schema: VPHASDR3
    ERROR:root:HTTP Error 404:
    Traceback (most recent call last):
      File "/usr/local/lib/python3.5/dist-packages/firethorn/models/base/base_object.py", line 90, in get_json
        with urllib.request.urlopen( req, data) as response:
      File "/usr/lib/python3.5/urllib/request.py", line 163, in urlopen
        return opener.open(url, data, timeout)
      File "/usr/lib/python3.5/urllib/request.py", line 472, in open
        response = meth(req, response)
      File "/usr/lib/python3.5/urllib/request.py", line 582, in http_response
        'http', request, response, code, msg, hdrs)
      File "/usr/lib/python3.5/urllib/request.py", line 510, in error
        return self._call_chain(*args)
      File "/usr/lib/python3.5/urllib/request.py", line 444, in _call_chain
        result = func(*args)
      File "/usr/lib/python3.5/urllib/request.py", line 590, in http_error_default
        raise HTTPError(req.full_url, code, msg, hdrs, fp)
    urllib.error.HTTPError: HTTP Error 404:
    ERROR:root:Expecting value: line 1 column 1 (char 0)
    Traceback (most recent call last):
      File "/usr/local/lib/python3.5/dist-packages/firethorn/models/adql/adql_resource.py", line 112, in import_jdbc_schema
        response_json_list = json.loads(response.text)
      File "/usr/lib/python3.5/json/__init__.py", line 319, in loads
        return _default_decoder.decode(s)
      File "/usr/lib/python3.5/json/decoder.py", line 339, in decode
        obj, end = self.raw_decode(s, idx=_w(s, 0).end())
      File "/usr/lib/python3.5/json/decoder.py", line 357, in raw_decode
        raise JSONDecodeError("Expecting value", s, err.value) from None
    json.decoder.JSONDecodeError: Expecting value: line 1 column 1 (char 0)
    Importing JDBC Schema: VVVDR4
    ERROR:root:HTTP Error 404:
    Traceback (most recent call last):
      File "/usr/local/lib/python3.5/dist-packages/firethorn/models/base/base_object.py", line 90, in get_json
        with urllib.request.urlopen( req, data) as response:
      File "/usr/lib/python3.5/urllib/request.py", line 163, in urlopen
        return opener.open(url, data, timeout)
      File "/usr/lib/python3.5/urllib/request.py", line 472, in open
        response = meth(req, response)
      File "/usr/lib/python3.5/urllib/request.py", line 582, in http_response
        'http', request, response, code, msg, hdrs)
      File "/usr/lib/python3.5/urllib/request.py", line 510, in error
        return self._call_chain(*args)
      File "/usr/lib/python3.5/urllib/request.py", line 444, in _call_chain
        result = func(*args)
      File "/usr/lib/python3.5/urllib/request.py", line 590, in http_error_default
        raise HTTPError(req.full_url, code, msg, hdrs, fp)
    urllib.error.HTTPError: HTTP Error 404:
    ERROR:root:Expecting value: line 1 column 1 (char 0)
    Traceback (most recent call last):
      File "/usr/local/lib/python3.5/dist-packages/firethorn/models/adql/adql_resource.py", line 112, in import_jdbc_schema
        response_json_list = json.loads(response.text)
      File "/usr/lib/python3.5/json/__init__.py", line 319, in loads
        return _default_decoder.decode(s)
      File "/usr/lib/python3.5/json/decoder.py", line 339, in decode
        obj, end = self.raw_decode(s, idx=_w(s, 0).end())
      File "/usr/lib/python3.5/json/decoder.py", line 357, in raw_decode
        raise JSONDecodeError("Expecting value", s, err.value) from None
    json.decoder.JSONDecodeError: Expecting value: line 1 column 1 (char 0)
    Importing JDBC Schema: SDSSDR7
    ERROR:root:HTTP Error 404:
    Traceback (most recent call last):
      File "/usr/local/lib/python3.5/dist-packages/firethorn/models/base/base_object.py", line 90, in get_json
        with urllib.request.urlopen( req, data) as response:
      File "/usr/lib/python3.5/urllib/request.py", line 163, in urlopen
        return opener.open(url, data, timeout)
      File "/usr/lib/python3.5/urllib/request.py", line 472, in open
        response = meth(req, response)
      File "/usr/lib/python3.5/urllib/request.py", line 582, in http_response
        'http', request, response, code, msg, hdrs)
      File "/usr/lib/python3.5/urllib/request.py", line 510, in error
        return self._call_chain(*args)
      File "/usr/lib/python3.5/urllib/request.py", line 444, in _call_chain
        result = func(*args)
      File "/usr/lib/python3.5/urllib/request.py", line 590, in http_error_default
        raise HTTPError(req.full_url, code, msg, hdrs, fp)
    urllib.error.HTTPError: HTTP Error 404:
    ERROR:root:Expecting value: line 1 column 1 (char 0)
    Traceback (most recent call last):
      File "/usr/local/lib/python3.5/dist-packages/firethorn/models/adql/adql_resource.py", line 112, in import_jdbc_schema
        response_json_list = json.loads(response.text)
      File "/usr/lib/python3.5/json/__init__.py", line 319, in loads
        return _default_decoder.decode(s)
      File "/usr/lib/python3.5/json/decoder.py", line 339, in decode
        obj, end = self.raw_decode(s, idx=_w(s, 0).end())
      File "/usr/lib/python3.5/json/decoder.py", line 357, in raw_decode
        raise JSONDecodeError("Expecting value", s, err.value) from None
    json.decoder.JSONDecodeError: Expecting value: line 1 column 1 (char 0)
    Importing JDBC Schema: SDSSDR9

    ....
    ....

    TAP Service available at: http://gillian:8080/firethorn/tap/54/


    #
    # Iterate the metadata tree
    for schema in resource.select_schemas():
        for table in schema.select_tables():
            print(
                "table  [{}][{}][{}]".format(
                    schema.name(),
                    table.name(),
                    table.count(),
                    )
                )
            query_str = "SELECT TOP 10 * FROM {}.{}".format(
                schema.name(),
                table.name()
                )
            query_obj = resource.create_query(
                query_str,
                "COMPLETED",
                None,
                3000000
                )
            py_table = query_obj.table().as_astropy()
            py_table.pprint()


    ....
    ....
    ....
    ....


    table  [BestDR9][Region][-1]
    ERROR:root:unknown url type: 'None'
    Traceback (most recent call last):
      File "/usr/local/lib/python3.5/dist-packages/firethorn/models/base/base_object.py", line 88, in get_json
        req = urllib.request.Request( ident, headers=self.account.get_identity_as_headers())
      File "/usr/lib/python3.5/urllib/request.py", line 269, in __init__
        self.full_url = url
      File "/usr/lib/python3.5/urllib/request.py", line 295, in full_url
        self._parse()
      File "/usr/lib/python3.5/urllib/request.py", line 324, in _parse
        raise ValueError("unknown url type: %r" % self.full_url)
    ValueError: unknown url type: 'None'
    ERROR:root:unknown url type: 'None'
    Traceback (most recent call last):
      File "/usr/local/lib/python3.5/dist-packages/firethorn/models/base/base_object.py", line 88, in get_json
        req = urllib.request.Request( ident, headers=self.account.get_identity_as_headers())
      File "/usr/lib/python3.5/urllib/request.py", line 269, in __init__
        self.full_url = url
      File "/usr/lib/python3.5/urllib/request.py", line 295, in full_url
        self._parse()
      File "/usr/lib/python3.5/urllib/request.py", line 324, in _parse
        raise ValueError("unknown url type: %r" % self.full_url)
    ValueError: unknown url type: 'None'
    ERROR:root:unknown url type: 'None'
    Traceback (most recent call last):
      File "/usr/local/lib/python3.5/dist-packages/firethorn/models/base/base_object.py", line 88, in get_json
        req = urllib.request.Request( ident, headers=self.account.get_identity_as_headers())
      File "/usr/lib/python3.5/urllib/request.py", line 269, in __init__
        self.full_url = url
      File "/usr/lib/python3.5/urllib/request.py", line 295, in full_url
        self._parse()
      File "/usr/lib/python3.5/urllib/request.py", line 324, in _parse
        raise ValueError("unknown url type: %r" % self.full_url)
    ValueError: unknown url type: 'None'
    Traceback (most recent call last):
      File "<stdin>", line 22, in <module>
      File "/usr/local/lib/python3.5/dist-packages/firethorn/models/adql/adql_table.py", line 94, in as_astropy
        if (self.count()>config.maxrows):
    TypeError: unorderable types: NoneType() > int()
    >>>


